/var/lib/oar/.batch_job_bashrc: line 5: /home/cmuller/.bashrc: No such file or directory

Attaching package: ‘dplyr’

The following objects are masked from ‘package:stats’:

    filter, lag

The following objects are masked from ‘package:base’:

    intersect, setdiff, setequal, union

Warning message:
package ‘dplyr’ was built under R version 4.4.3 
Warning message:
package ‘stringr’ was built under R version 4.4.3 

Attaching package: ‘mice’

The following object is masked from ‘package:stats’:

    filter

The following objects are masked from ‘package:base’:

    cbind, rbind

Warning messages:
1: package ‘mice’ was built under R version 4.4.3 
2: package ‘CALIBERrfimpute’ was built under R version 4.4.3 
Error in str_split(gsub("\\[|\\]", "", df_set_up$true_beta[i]), " ")[[1]] : 
  subscript out of bounds
Execution halted
/var/lib/oar/.batch_job_bashrc: line 5: /home/cmuller/.bashrc: No such file or directory

Attaching package: ‘dplyr’

The following objects are masked from ‘package:stats’:

    filter, lag

The following objects are masked from ‘package:base’:

    intersect, setdiff, setequal, union

Warning message:
package ‘dplyr’ was built under R version 4.4.3 
Warning message:
package ‘stringr’ was built under R version 4.4.3 

Attaching package: ‘mice’

The following object is masked from ‘package:stats’:

    filter

The following objects are masked from ‘package:base’:

    cbind, rbind

Warning messages:
1: package ‘mice’ was built under R version 4.4.3 
2: package ‘CALIBERrfimpute’ was built under R version 4.4.3 
Traceback (most recent call last):
  File "/home/cmuller/.local/lib/python3.11/site-packages/pandas/core/indexes/base.py", line 3805, in get_loc
    return self._engine.get_loc(casted_key)
           ^^^^^^^^^^^^^^^^^^^^^^^^^^^^^^^^
  File "index.pyx", line 167, in pandas._libs.index.IndexEngine.get_loc
  File "index.pyx", line 196, in pandas._libs.index.IndexEngine.get_loc
  File "pandas/_libs/hashtable_class_helper.pxi", line 7081, in pandas._libs.hashtable.PyObjectHashTable.get_item
  File "pandas/_libs/hashtable_class_helper.pxi", line 7089, in pandas._libs.hashtable.PyObjectHashTable.get_item
KeyError: 'true_beta'

The above exception was the direct cause of the following exception:

Traceback (most recent call last):
  File "/home/cmuller/logistic_with_NAs/3_train_methods.py", line 69, in <module>
    true_beta = df_set_up["true_beta"][i]
                ~~~~~~~~~^^^^^^^^^^^^^
  File "/home/cmuller/.local/lib/python3.11/site-packages/pandas/core/frame.py", line 4102, in __getitem__
    indexer = self.columns.get_loc(key)
              ^^^^^^^^^^^^^^^^^^^^^^^^^
  File "/home/cmuller/.local/lib/python3.11/site-packages/pandas/core/indexes/base.py", line 3812, in get_loc
    raise KeyError(key) from err
KeyError: 'true_beta'
